Workbook

Sheet Cover
A1: Utz Brands — Was Intersnack's $14.25 Offer Fair to Public Shareholders?
A2: Independent valuation by Taruni Komma | Deal announced July 20, 2026 | Portfolio exercise from public filings, not investment advice
A4: KEY OUTPUTS (live)
A5: Offer price per share | B5: ='Deal & Inputs'!$B$4 -> 14.25
A6: Enterprise value at offer ($mm) | B6: ='Deal & Inputs'!$B$22 -> 2872.925
A7: EV / LTM adjusted EBITDA | B7: ='Deal & Inputs'!$B$23 -> 12.695205
A8: Premium to unaffected price | B8: ='Deal & Inputs'!$B$26 -> 0.91018767
A9: DCF value — selected case (midpoint) | B9: =DCF!B71 -> 12.026621
A10: Trading comparables range | B10: =TEXT('Trading Comps'!B32,"$0.00")&" – "&TEXT('Trading Comps'!C32,"$0.00") -> $4.65 – $7.75
A11: Precedent transactions range | B11: =TEXT('Precedent Transactions'!B25,"$0.00")&" – "&TEXT('Precedent Transactions'!C25,"$0.00") -> $10.85 – $15.50
A13: WORKBOOK
A14: • Deal & Inputs — offer, premiums, capitalization, implied deal multiples, offer history
A15: • DCF — management projections, downside case selector, WACC build, sensitivity
A16: • Trading Comps — Citi's mid-cap food peer set plus large-cap snack reference
A17: • Precedent Transactions — five snack/food deals with disclosed or calculated multiples
A18: • Football Field — all ranges vs. the offer and vs. the special committee advisor's ranges
A19: • Sources — every filing and data page used

Sheet Deal & Inputs
A1: Utz Brands (UTZ) — Intersnack Take-Private: Deal Terms and Key Inputs
A2: $ in millions except per share. Blue = sourced input or assumption. Valuation date: June 28, 2026 (last balance sheet before announcement).
A3: OFFER
A4: Offer price per share (cash) | B4: 14.25 | C4: Announced July 20, 2026 (Utz/Intersnack release)
A5: Unaffected share price (July 20, 2026 close) | B5: 7.46 | C5: Implied by stated ~91% premium; matches proxy summary
A6: 30-day VWAP before announcement | B6: 7.44 | C6: Proxy summary (For Fairness Sake)
A7: 90-day VWAP before announcement | B7: 7.54 | C7: Proxy summary (For Fairness Sake)
A8: 52-week high (July 23, 2025) | B8: 14.67 | C8: Citi special committee materials, Apr 17, 2026 (13E-3 exhibit)
A9: 52-week low (March 25, 2026) | B9: 7.12 | C9: Citi special committee materials, Apr 17, 2026 (13E-3 exhibit)
A10: CAPITALIZATION (June 28, 2026)
A11: Fully diluted shares (mm) | B11: 146.1 | C11: Citi DCF share count incl. options and RSUs (13E-3 exhibit, Mar 31, 2026)
A12: Gross debt incl. finance leases | B12: 849.6 | C12: Q2 2026 earnings release
A13: Cash and equivalents | B13: 58.6 | C13: Q2 2026 earnings release
A14: Net debt | B14: =B12-B13 -> 791 | C14: Company-reported net debt $791.0mm
A15: ADJUSTED EBITDA
A16: LTM adjusted EBITDA (June 28, 2026) | B16: 226.3 | C16: Q2 2026 earnings release (net leverage 3.5x)
A17: FY2025 adjusted EBITDA | B17: 216.5 | C17: Q4 2025 earnings release
A18: 2026 plan (AOP) adjusted EBITDA | B18: 232 | C18: Management projections in Citi materials (13E-3 exhibit)
A19: 2027E adjusted EBITDA | B19: 246 | C19: Management projections in Citi materials (13E-3 exhibit)
A20: IMPLIED DEAL VALUE
A21: Equity value at offer | B21: =B4*B11 -> 2081.925
A22: Enterprise value at offer | B22: =B21+B14 -> 2872.925 | C22: Company stated ~ $2.9bn
A23: EV / LTM adjusted EBITDA | B23: =B22/B16 -> 12.695205
A24: EV / 2026 plan adjusted EBITDA | B24: =B22/B18 -> 12.383297
A25: EV / 2027E adjusted EBITDA | B25: =B22/B19 -> 11.678557
A26: Premium to unaffected price | B26: =B4/B5-1 -> 0.91018767
A27: Premium to 30-day VWAP | B27: =B4/B6-1 -> 0.91532258
A28: Premium to 90-day VWAP | B28: =B4/B7-1 -> 0.88992042
A29: Premium / (discount) to 52-week high | B29: =B4/B8-1 -> -0.028629857
A31: OFFER HISTORY (Intersnack proposals)
A32: Date | B32: Price per share | C32: Premium to $7.46
A33: Mar 18, 2026 | B33: 11 | C33: =B33/$B$5-1 -> 0.47453083
A34: Apr 2, 2026 | B34: 11.75 | C34: =B34/$B$5-1 -> 0.57506702
A35: Apr 16, 2026 | B35: 13.75 | C35: =B35/$B$5-1 -> 0.84316354
A36: Apr 21, 2026 | B36: 14 | C36: =B36/$B$5-1 -> 0.8766756
A37: Jun 16, 2026 | B37: 14.1 | C37: =B37/$B$5-1 -> 0.89008043
A38: Jun 20, 2026 (agreed) | B38: 14.25 | C38: =B38/$B$5-1 -> 0.91018767
A39: Source: proxy summary (For Fairness Sake) and Citi materials. Each round raised the price; total increase 29.5% from the first proposal.
A41: DEAL STRUCTURE NOTES
A42: • Founding Rice and Lissette family rolls equity and owns 50% post-close with Intersnack; they agreed to vote ~42% of shares in favor.
...

Sheet DCF
A1: Discounted Cash Flow — Management Case and Downside Case
A2: Projections: management forecasts shown in Citi's special committee materials (13E-3 exhibit). Downside case: growth 1 pt lower and half of the planned margin expansion from 2027. Valuation date June 28, 2026; mid-year discounting.
A4: Case selector (1 = Management, 2 = Downside) | B4: 1 | C4: =IF($B$4=1,"Management case","Downside case") -> Management case
A6: ($ in millions) | B6: 2026 plan | C6: 2027E | D6: 2028E | E6: 2029E | F6: 2030E | G6: 2031E | H6: Terminal
A7: MANAGEMENT INPUTS (as provided)
A8: Net sales | B8: 1513 | C8: 1541 | D8: 1609 | E8: 1673 | F8: 1770 | G8: 1803
A9: Adjusted EBITDA | B9: 232 | C9: 246 | D9: 263 | E9: 283 | F9: 310 | G9: 325
A10: D&A | B10: 104 | C10: 107 | D10: 104 | E10: 104 | F10: 102 | G10: 102 | H10: 58
A11: Share-based compensation | B11: 17 | C11: 17 | D11: 17 | E11: 17 | F11: 17 | G11: 17 | H11: 17
A12: Restructuring & transformation | B12: 45 | C12: 25 | D12: 15 | E12: 15 | F12: 15 | G12: 15 | H12: 0
A13: Proceeds from asset sales | B13: 25 | C13: 0 | D13: 0 | E13: 0 | F13: 0 | G13: 0 | H13: 0
A14: Tax rate | B14: 0.1 | C14: 0.277 | D14: 0.277 | E14: 0.277 | F14: 0.277 | G14: 0.277 | H14: 0.277
A15: PP&E capex | B15: 61 | C15: 42 | D15: 48 | E15: 50 | F15: 52 | G15: 52 | H15: 52
A16: Cloud computing capex | B16: 20 | C16: 11 | D16: 9 | E16: 8 | F16: 6 | G16: 6 | H16: 6
A17: Increase in net working capital | B17: 0 | C17: 8 | D17: 8 | E17: 8 | F17: 8 | G17: 9 | H17: 5
A18: Terminal column: management normalized D&A to the capex level; 2026 plan and 2030E are 53-week years.
A20: DOWNSIDE ADJUSTMENTS
A21: Reduction in annual sales growth (from 2027) | B21: 0.01
A22: Share of planned margin expansion achieved | B22: 0.5
A23: Management said in the proxy that it saw more downside than upside risk to its projections.
A25: UNLEVERED FREE CASH FLOW (selected case)
A26: ($ in millions) | B26: 2026 plan | C26: 2027E | D26: 2028E | E26: 2029E | F26: 2030E | G26: 2031E | H26: Terminal
A27: Net sales | B27: =B8 -> 1513 | C27: =B27*(C8/B8-IF($B$4=2,$B$21,0)) -> 1541 | D27: =C27*(D8/C8-IF($B$4=2,$B$21,0)) -> 1609 | E27: =D27*(E8/D8-IF($B$4=2,$B$21,0)) -> 1673 | F27: =E27*(F8/E8-IF($B$4=2,$B$21,0)) -> 1770 | G27: =F27*(G8/F8-IF($B$4=2,$B$21,0)) -> 1803 | H27: =G27 -> 1803
A28: Adjusted EBITDA margin | B28: =B9/B8 -> 0.15333774 | C28: =IF($B$4=1,C9/C8,$B9/$B8+$B$22*(C9/C8-$B9/$B8)) -> 0.1596366 | D28: =IF($B$4=1,D9/D8,$B9/$B8+$B$22*(D9/D8-$B9/$B8)) -> 0.16345556 | E28: =IF($B$4=1,E9/E8,$B9/$B8+$B$22*(E9/E8-$B9/$B8)) -> 0.1691572 | F28: =IF($B$4=1,F9/F8,$B9/$B8+$B$22*(F9/F8-$B9/$B8)) -> 0.17514124 | G28: =IF($B$4=1,G9/G8,$B9/$B8+$B$22*(G9/G8-$B9/$B8)) -> 0.18025513 | H28: =IF($B$4=1,G9/G8,$B9/$B8+$B$22*(G9/G8-$B9/$B8)) -> 0.18025513
A29: Adjusted EBITDA | B29: =B27*B28 -> 232 | C29: =C27*C28 -> 246 | D29: =D27*D28 -> 263 | E29: =E27*E28 -> 283 | F29: =F27*F28 -> 310 | G29: =G27*G28 -> 325 | H29: =H27*H28 -> 325
A30: (–) D&A | B30: =-B10 -> -104 | C30: =-C10 -> -107 | D30: =-D10 -> -104 | E30: =-E10 -> -104 | F30: =-F10 -> -102 | G30: =-G10 -> -102 | H30: =-H10 -> -58
A31: (–) Share-based compensation | B31: =-B11 -> -17 | C31: =-C11 -> -17 | D31: =-D11 -> -17 | E31: =-E11 -> -17 | F31: =-F11 -> -17 | G31: =-G11 -> -17 | H31: =-H11 -> -17
A32: (–) Restructuring & transformation | B32: =-B12 -> -45 | C32: =-C12 -> -25 | D32: =-D12 -> -15 | E32: =-E12 -> -15 | F32: =-F12 -> -15 | G32: =-G12 -> -15 | H32: =-H12 -> 0
A33: (+) Asset sale proceeds | B33: =B13 -> 25 | C33: =C13 -> 0 | D33: =D13 -> 0 | E33: =E13 -> 0 | F33: =F13 -> 0 | G33: =G13 -> 0 | H33: =H13 -> 0
A34: EBIT (cash-adjusted) | B34: =B29+B30+B31+B32+B33 -> 91 | C34: =C29+C30+C31+C32+C33 -> 97 | D34: =D29+D30+D31+D32+D33 -> 127 | E34: =E29+E30+E31+E32+E33 -> 147 | F34: =F29+F30+F31+F32+F33 -> 176 | G34: =G29+G30+G31+G32+G33 -> 191 | H34: =H29+H30+H31+H32+H33 -> 250
A35: (–) Taxes | B35: =-MAX(0,B34)*B14 -> -9.1 | C35: =-MAX(0,C34)*C14 -> -26.869 | D35: =-MAX(0,D34)*D14 -> -35.179 | E35: =-MAX(0,E34)*E14 -> -40.719 | F35: =-MAX(0,F34)*F14 -> -48.752 | G35: =-MAX(0,G34)*G14 -> -52.907 | H35: =-MAX(0,H34)*H14 -> -69.25
A36: NOPAT | B36: =B34+B35 -> 81.9 | C36: =C34+C35 -> 70.131 | D36: =D34+D35 -> 91.821 | E36: =E34+E35 -> 106.281 | F36: =F34+F35 -> 127.248 | G36: =G34+G35 -> 138.093 | H36: =H34+H35 -> 180.75
A37: (+) D&A | B37: =-B30 -> 104 | C37: =-C30 -> 107 | D37: =-D30 -> 104 | E37: =-E30 -> 104 | F37: =-F30 -> 102 | G37: =-G30 -> 102 | H37: =-H30 -> 58
A38: (–) PP&E capex | B38: =-B15 -> -61 | C38: =-C15 -> -42 | D38: =-D15 -> -48 | E38: =-E15 -> -50 | F38: =-F15 -> -52 | G38: =-G15 -> -52 | H38: =-H15 -> -52
A39: (–) Cloud capex | B39: =-B16 -> -20 | C39: =-C16 -> -11 | D39: =-D16 -> -9 | E39: =-E16 -> -8 | F39: =-F16 -> -6 | G39: =-G16 -> -6 | H39: =-H16 -> -6
A40: (–) Increase in NWC | B40: =-B17 -> 0 | C40: =-C17 -> -8 | D40: =-D17 -> -8 | E40: =-E17 -> -8 | F40: =-F17 -> -8 | G40: =-G17 -> -9 | H40: =-H17 -> -5
A41: Unlevered free cash flow | B41: =B36+B37+B38+B39+B40 -> 104.9 | C41: =C36+C37+C38+C39+C40 -> 116.131 | D41: =D36+D37+D38+D39+D40 -> 130.821 | E41: =E36+E37+E38+E39+E40 -> 144.281 | F41: =F36+F37+F38+F39+F40 -> 163.248 | G41: =G36+G37+G38+G39+G40 -> 173.093 | H41: =H36+H37+H38+H39+H40 -> 175.75
A42: Check: management case reproduces management's unlevered FCF of $105 / 116 / 131 / 144 / 162 / 173 and terminal $176mm (±$1 rounding).
A44: COST OF CAPITAL (as of announcement week)
A45: Risk-free rate (10-year Treasury, week of July 17, 2026) | B45: 0.0457 | C45: YCharts weekly 10-year Treasury rate
...

Sheet Trading Comps
A1: Selected Public Companies — Mid-Cap Food (Citi's peer set) and Large-Cap Snack Reference
A2: Market data at close Oct 16, 2026 (StockAnalysis.com); EBITDA = trailing twelve months as reported by the data provider. Note: comparables are post-announcement prices; food stocks fell further after July 2026.
A4: Company | B4: Ticker | C4: Share price | D4: Market cap | E4: Enterprise value | F4: LTM revenue | G4: LTM EBITDA | H4: EV / Revenue | I4: EV / EBITDA | J4: EBITDA margin
A5: MID-CAP FOOD PEERS (used for valuation)
A6: Post Holdings | B6: POST | C6: 78.53 | D6: 3450 | E6: 10820 | F6: 8410 | G6: 1450 | H6: =E6/F6 -> 1.2865636 | I6: =E6/G6 -> 7.462069 | J6: =G6/F6 -> 0.17241379
A7: The Marzetti Company | B7: MZTI | C7: 104.47 | D7: 2850 | E7: 3080 | F7: 1930 | G7: 305.19 | H7: =E7/F7 -> 1.5958549 | I7: =E7/G7 -> 10.092074 | J7: =G7/F7 -> 0.15812953
A8: Flowers Foods | B8: FLO | C8: 6.11 | D8: 1300 | E8: 3250 | F8: 5220 | G8: 486.93 | H8: =E8/F8 -> 0.62260536 | I8: =E8/G8 -> 6.6744707 | J8: =G8/F8 -> 0.093281609
A9: BellRing Brands | B9: BRBR | C9: 9.43 | D9: 1100 | E9: 2220 | F9: 2350 | G9: 331.9 | H9: =E9/F9 -> 0.94468085 | I9: =E9/G9 -> 6.6887617 | J9: =G9/F9 -> 0.14123404
A10: B&G Foods | B10: BGS | C10: 2.4 | D10: 195.06 | E10: 2180 | F10: 1770 | G10: 258.69 | H10: =E10/F10 -> 1.2316384 | I10: =E10/G10 -> 8.4270749 | J10: =G10/F10 -> 0.14615254
A11: Simply Good Foods | B11: SMPL | C11: 11.2 | D11: 989.87 | E11: 1310 | F11: 1390 | G11: 217.48 | H11: =E11/F11 -> 0.94244604 | I11: =E11/G11 -> 6.0235424 | J11: =G11/F11 -> 0.15646043
A12: J&J Snack Foods | B12: JJSF | C12: 78.75 | D12: 1470 | E12: 1600 | F12: 1520 | G12: 155.78 | H12: =E12/F12 -> 1.0526316 | I12: =E12/G12 -> 10.270895 | J12: =G12/F12 -> 0.10248684
A13: Median | H13: =MEDIAN(H6:H12) -> 1.0526316 | I13: =MEDIAN(I6:I12) -> 7.462069 | J13: =MEDIAN(J6:J12) -> 0.14615254
A14: 25th percentile | H14: =QUARTILE(H6:H12,1) -> 0.94356345 | I14: =QUARTILE(I6:I12,1) -> 6.6816162 | J14: =QUARTILE(J6:J12,1) -> 0.12186044
A15: 75th percentile | H15: =QUARTILE(H6:H12,3) -> 1.259101 | I15: =QUARTILE(I6:I12,3) -> 9.2595743 | J15: =QUARTILE(J6:J12,3) -> 0.15729498
A16: Mean | H16: =AVERAGE(H6:H12) -> 1.0966315 | I16: =AVERAGE(I6:I12) -> 7.9484125 | J16: =AVERAGE(J6:J12) -> 0.13859411
A18: LARGE-CAP SNACK & FOOD (reference only — far larger and more diversified)
A19: Campbell's | B19: CPB | C19: 19.87 | D19: 5930 | E19: 12980 | F19: 9740 | G19: 1620 | H19: =E19/F19 -> 1.3326489 | I19: =E19/G19 -> 8.0123457 | J19: =G19/F19 -> 0.16632444
A20: General Mills | B20: GIS | C20: 33.13 | D20: 17710 | E20: 30900 | F20: 18300 | G20: 3420 | H20: =E20/F20 -> 1.6885246 | I20: =E20/G20 -> 9.0350877 | J20: =G20/F20 -> 0.18688525
A21: Hershey | B21: HSY | C21: 170.83 | D21: 34320 | E21: 39460 | F21: 12160 | G21: 2720 | H21: =E21/F21 -> 3.2450658 | I21: =E21/G21 -> 14.507353 | J21: =G21/F21 -> 0.22368421
A22: Mondelez | B22: MDLZ | C22: 63.91 | D22: 81570 | E22: 101910 | F22: 39680 | G22: 6080 | H22: =E22/F22 -> 2.5682964 | I22: =E22/G22 -> 16.761513 | J22: =G22/F22 -> 0.15322581
A24: UTZ — IMPLIED VALUE
A25: Utz LTM adjusted EBITDA | B25: ='Deal & Inputs'!$B$16 -> 226.3
A26: Utz LTM adjusted EBITDA margin | B26: ='Deal & Inputs'!$B$16/1452 -> 0.15585399 | C26: LTM net sales ≈ $1,452mm (FY2025 $1,438.8mm + H1 2026 growth of $14.3mm)
A28: Selected EV / LTM EBITDA range | B28: Low | C28: High
A29: Multiple (≈ peer 25th–75th percentile, rounded) | B29: 6.5 | C29: 8.5
A30: Implied enterprise value | B30: =B29*$B$25 -> 1470.95 | C30: =C29*$B$25 -> 1923.55
A31: Less net debt → equity value | B31: =B30-'Deal & Inputs'!$B$14 -> 679.95 | C31: =C30-'Deal & Inputs'!$B$14 -> 1132.55
A32: Implied value per share | B32: =B31/'Deal & Inputs'!$B$11 -> 4.6540041 | C32: =C31/'Deal & Inputs'!$B$11 -> 7.7518823
A34: Peers' EBITDA is the data provider's figure, which may include some one-time items; Utz uses company-adjusted EBITDA.

Sheet Precedent Transactions
A1: Selected Precedent Transactions — U.S. Packaged Snacks and Food
A2: Multiples as disclosed in deal announcements, or calculated as EV ÷ target's last twelve months adjusted EBITDA where not disclosed.
A4: Acquirer | B4: Target | C4: Announced | D4: Enterprise value ($bn) | E4: EV / EBITDA | F4: Basis | G4: Source
A5: Mars | B5: Kellanova | C5: Aug 2024 | D5: 35.9 | E5: 16.4 | F5: LTM adj. EBITDA (disclosed) | G5: https://www.nasdaq.com/press-release/mars-acquire-kellanova-2024-08-14
A6: J.M. Smucker | B6: Hostess Brands | C6: Sep 2023 | D6: 5.6 | E6: 17.2 | F6: 2023E adj. EBITDA (disclosed) | G6: https://www.preparedfoods.com/articles/128505-the-j-m-smucker-co-to-acquire-hostess-brands
A7: Campbell Soup | B7: Snyder's-Lance | C7: Dec 2017 | D7: 6.1 | E7: 19.9 | F7: CY2017E adj. EBITDA (disclosed) | G7: https://www.sec.gov/Archives/edgar/data/0000016732/000095015917000274/ex99-1.htm
A8: Ferrero | B8: WK Kellogg | C8: Jul 2025 | D8: 3.1 | E8: =D8*1000/(275+134-161) -> 12.5 | F8: LTM Jun-25 adj. EBITDA (calculated) | G8: https://www.nasdaq.com/press-release/ferrero-acquire-wk-kellogg-co-2025-07-10
A9: Investindustrial | B9: TreeHouse Foods | C9: Nov 2025 | D9: 2.9 | E9: =D9*1000/(337.4+222.4-219.1) -> 8.5118873 | F9: LTM Sep-25 adj. EBITDA (calculated) | G9: https://www.treehousefoods.com/news-and-media/press-release-details/2025/TreeHouse-Foods-Inc--Reports-Third-Quarter-2025-Results/default.aspx
A10: Median | E10: =MEDIAN(E5:E9) -> 16.4
A11: Mean | E11: =AVERAGE(E5:E9) -> 14.902377
A12: Low | E12: =MIN(E5:E9) -> 8.5118873
A13: High | E13: =MAX(E5:E9) -> 19.9
A15: WK Kellogg: $3.1bn ÷ ($275mm FY2024 + $134mm H1 2025 − $161mm H1 2024) = $248mm LTM.
A16: TreeHouse: $2.9bn ÷ ($337.4mm FY2024 + $222.4mm 9M 2025 − $219.1mm 9M 2024) = $340.7mm LTM.
A17: The three large branded deals (16–20x) involved faster-growing, higher-margin brands and big synergy cases;
A18: the two most recent, similar-sized deals (8.5x, 12.5x) are the closest references for Utz.
A20: UTZ — IMPLIED VALUE
A21: Selected EV / LTM EBITDA range | B21: Low | C21: High
A22: Multiple (anchored on recent similar-size deals) | B22: 10.5 | C22: 13.5
A23: Implied enterprise value | B23: =B22*'Deal & Inputs'!$B$16 -> 2376.15 | C23: =C22*'Deal & Inputs'!$B$16 -> 3055.05
A24: Less net debt → equity value | B24: =B23-'Deal & Inputs'!$B$14 -> 1585.15 | C24: =C23-'Deal & Inputs'!$B$14 -> 2264.05
A25: Implied value per share | B25: =B24/'Deal & Inputs'!$B$11 -> 10.84976 | C25: =C24/'Deal & Inputs'!$B$11 -> 15.496578

Sheet Football Field
A1: Valuation Summary — Where Does the $14.25 Offer Fall?
A2: Per-share values. Independent ranges (this analysis) beside the special committee advisor's ranges for reference.
A4: Method | B4: Low | C4: High | D4: Midpoint | E4: Offer vs. midpoint | F4: Citi low | G4: Citi high | H4: Basis
A5: DCF — management case | B5: =MIN(DCF!B79:D81) -> 9.7778171 | C5: =MAX(DCF!B79:D81) -> 15.181842 | D5: =DCF!C80 -> 12.036541 | E5: ='Deal & Inputs'!$B$4/D5-1 -> 0.18389495 | F5: 10.6 | G5: 14.8 | H5: WACC ±0.5%, terminal growth 1.5%–2.5%; midpoint = base WACC and 2.0% growth (DCF sheet with case 1)
A6: DCF — downside case | B6: 7.6341 | C6: 12.1859 | D6: 9.5369 | E6: ='Deal & Inputs'!$B$4/D6-1 -> 0.49419623 | H6: Growth −1 pt and half the margin expansion; values captured by running the DCF sheet with case 2
A7: Trading comparables | B7: ='Trading Comps'!B32 -> 4.6540041 | C7: ='Trading Comps'!C32 -> 7.7518823 | D7: =AVERAGE(B7:C7) -> 6.2029432 | E7: ='Deal & Inputs'!$B$4/D7-1 -> 1.2972966 | F7: 5.7 | G7: 9 | H7: 6.5x–8.5x LTM EBITDA (Citi: 6.6x–8.6x 2027E EBITDA)
A8: Precedent transactions | B8: ='Precedent Transactions'!B25 -> 10.84976 | C8: ='Precedent Transactions'!C25 -> 15.496578 | D8: =AVERAGE(B8:C8) -> 13.173169 | E8: ='Deal & Inputs'!$B$4/D8-1 -> 0.081744259 | F8: 10.15 | G8: 13.15 | H8: 10.5x–13.5x LTM EBITDA (Citi: 10.4x–12.4x)
A9: Premiums paid (30%–50%) | B9: ='Deal & Inputs'!$B$5*1.3 -> 9.698 | C9: ='Deal & Inputs'!$B$5*1.5 -> 11.19 | D9: =AVERAGE(B9:C9) -> 10.444 | E9: ='Deal & Inputs'!$B$4/D9-1 -> 0.36441976 | F9: 9.35 | G9: 10.8 | H9: Typical all-cash premiums on unaffected price
A10: 52-week trading range | B10: ='Deal & Inputs'!$B$9 -> 7.12 | C10: ='Deal & Inputs'!$B$8 -> 14.67 | D10: =AVERAGE(B10:C10) -> 10.895 | E10: ='Deal & Inputs'!$B$4/D10-1 -> 0.30793942 | H10: Reference only
A12: Offer price | B12: ='Deal & Inputs'!$B$4 -> 14.25
A13: Unaffected price (July 20, 2026) | B13: ='Deal & Inputs'!$B$5 -> 7.46
A15: Citi ranges: final fairness analysis as summarized from the proxy (For Fairness Sake); Citi's DCF used 7.9%–8.5% WACC.
A16: Citi also showed an illustrative future share price of $7.85–$11.45 and analyst targets of $8.00–$15.00.

Sheet Sources
A1: Sources
A3: Utz Q2 2026 earnings release (LTM EBITDA, debt, cash, shares, deal context) | B3: https://www.sec.gov/Archives/edgar/data/0001739566/000162828026052888/pressrelease-2026q2earning.htm
A4: Utz Q4 2025 earnings release (FY2025 adjusted EBITDA, net debt) | B4: https://www.sec.gov/Archives/edgar/data/1739566/000162828026007457/pressrelease-2025q4earning.htm
A5: Utz / Intersnack announcement (price, premium, EV, structure, advisors) | B5: https://investors.utzsnacks.com/news/news-details/2026/Utz-Brands-Inc--and-Intersnack-Group-GmbH--Co--KG-Announce-Agreement-to-Take-Utz-Private-and-Partnership-with-Founding-Family/default.aspx
A6: Citi special committee materials, Mar 31, 2026 (management projections, WACC inputs, Citi ranges) | B6: https://www.sec.gov/Archives/edgar/data/1739566/000119312526362085/d75151dex9916cxx.htm
A7: Citi special committee materials, Apr 17, 2026 (offer history, 52-week range) | B7: https://www.sec.gov/Archives/edgar/data/1739566/000119312526362085/d75151dex9916cxxi.htm
A8: Proxy summary: For Fairness Sake (final Citi ranges, VWAPs, offer path) | B8: https://forfairnesssake.substack.com/p/for-fairness-sake-utz-to-be-acquired
A9: 10-year Treasury rate, weekly (YCharts) | B9: https://ycharts.com/indicators/10_year_treasury_rate_weekly
A10: Peer market data: StockAnalysis.com statistics pages (POST, MZTI, FLO, BRBR, BGS, SMPL, JJSF, CPB, GIS, HSY, MDLZ) | B10: https://stockanalysis.com/stocks/
A11: Mars / Kellanova announcement | B11: https://www.nasdaq.com/press-release/mars-acquire-kellanova-2024-08-14
A12: Smucker / Hostess coverage | B12: https://www.preparedfoods.com/articles/128505-the-j-m-smucker-co-to-acquire-hostess-brands
A13: Campbell / Snyder's-Lance announcement (8-K) | B13: https://www.sec.gov/Archives/edgar/data/0000016732/000095015917000274/ex99-1.htm
A14: Ferrero / WK Kellogg announcement | B14: https://www.nasdaq.com/press-release/ferrero-acquire-wk-kellogg-co-2025-07-10
... A16: TreeHouse Q3 2025 release and Q4 2024 release (deal, adjusted EBITDA) | B16: https://www.treehousefoods.com/news-and-media/press-release-details/2025/TreeHouse-Foods-Inc--Reports-Third-Quarter-2025-Results/default.aspx
